<?xml version="1.0" ?>
<!-- =================================================================================== -->
<!-- |    This document was autogenerated by xacro from assets/gripper.xacro           | -->
<!-- |    EDITING THIS FILE BY HAND IS NOT RECOMMENDED                                 | -->
<!-- =================================================================================== -->
<robot name="gripper">
  <link name="arm1_base"/>
  <link name="arm1_link1">
    <visual>
      <origin rpy="0 0 0" xyz="0 0 0.075"/>
      <geometry>
        <cylinder length="0.15" radius="0.01"/>
      </geometry>
    </visual>
    <collision>
      <origin rpy="0 0 0" xyz="0 0 0.075"/>
      <geometry>
        <cylinder length="0.15" radius="0.01"/>
      </geometry>
    </collision>
    <inertial>
      <origin rpy="0 0 0" xyz="0 0 0.075"/>
      <mass value="1"/>
      <inertia ixx="0.0019" ixy="0.0" ixz="0.0" iyy="0.0019" iyz="0.0" izz="0.01125"/>
    </inertial>
  </link>
  <link name="arm1_link2">
    <visual>
      <origin rpy="0 0 0" xyz="0 0 0.125"/>
      <geometry>
        <cylinder length="0.25" radius="0.01"/>
      </geometry>
    </visual>
    <collision>
      <origin rpy="0 0 0" xyz="0 0 0.125"/>
      <geometry>
        <cylinder length="0.25" radius="0.01"/>
      </geometry>
    </collision>
    <inertial>
      <origin rpy="0 0 0" xyz="0 0 0.125"/>
      <mass value="1"/>
      <inertia ixx="0.005233333333333333" ixy="0.0" ixz="0.0" iyy="0.005233333333333333" iyz="0.0" izz="0.03125"/>
    </inertial>
  </link>
  <link name="arm1_link3">
    <visual>
      <origin rpy="0 0 0" xyz="0 0 0.125"/>
      <geometry>
        <cylinder length="0.25" radius="0.01"/>
      </geometry>
    </visual>
    <collision>
      <origin rpy="0 0 0" xyz="0 0 0.125"/>
      <geometry>
        <cylinder length="0.25" radius="0.01"/>
      </geometry>
    </collision>
    <inertial>
      <origin rpy="0 0 0" xyz="0 0 0.125"/>
      <mass value="1"/>
      <inertia ixx="0.005233333333333333" ixy="0.0" ixz="0.0" iyy="0.005233333333333333" iyz="0.0" izz="0.03125"/>
    </inertial>
  </link>
  <joint name="arm1_joint1" type="revolute">
    <parent link="arm1_base"/>
    <child link="arm1_link1"/>
    <limit effort="30" lower="0" upper="3.141592653589793" velocity="1.0"/>
    <origin rpy="-1.5707963267948966 0 0" xyz="-0.125 0.125 0"/>
    <axis xyz="1 0 0"/>
  </joint>
  <joint name="arm1_joint2" type="revolute">
    <parent link="arm1_link1"/>
    <child link="arm1_link2"/>
    <limit effort="30" lower="0" upper="3.141592653589793" velocity="1.0"/>
    <origin rpy="0 0 0" xyz="0 0 0.15"/>
    <axis xyz="1 0 0"/>
  </joint>
  <joint name="arm1_joint3" type="revolute">
    <parent link="arm1_link2"/>
    <child link="arm1_link3"/>
    <limit effort="30" lower="0" upper="3.141592653589793" velocity="1.0"/>
    <origin rpy="0 0 0" xyz="0 0 0.25"/>
    <axis xyz="1 0 0"/>
  </joint>
  <link name="arm2_base"/>
  <link name="arm2_link1">
    <visual>
      <origin rpy="0 0 0" xyz="0 0 0.075"/>
      <geometry>
        <cylinder length="0.15" radius="0.01"/>
      </geometry>
    </visual>
    <collision>
      <origin rpy="0 0 0" xyz="0 0 0.075"/>
      <geometry>
        <cylinder length="0.15" radius="0.01"/>
      </geometry>
    </collision>
    <inertial>
      <origin rpy="0 0 0" xyz="0 0 0.075"/>
      <mass value="1"/>
      <inertia ixx="0.0019" ixy="0.0" ixz="0.0" iyy="0.0019" iyz="0.0" izz="0.01125"/>
    </inertial>
  </link>
  <link name="arm2_link2">
    <visual>
      <origin rpy="0 0 0" xyz="0 0 0.125"/>
      <geometry>
        <cylinder length="0.25" radius="0.01"/>
      </geometry>
    </visual>
    <collision>
      <origin rpy="0 0 0" xyz="0 0 0.125"/>
      <geometry>
        <cylinder length="0.25" radius="0.01"/>
      </geometry>
    </collision>
    <inertial>
      <origin rpy="0 0 0" xyz="0 0 0.125"/>
      <mass value="1"/>
      <inertia ixx="0.005233333333333333" ixy="0.0" ixz="0.0" iyy="0.005233333333333333" iyz="0.0" izz="0.03125"/>
    </inertial>
  </link>
  <link name="arm2_link3">
    <visual>
      <origin rpy="0 0 0" xyz="0 0 0.125"/>
      <geometry>
        <cylinder length="0.25" radius="0.01"/>
      </geometry>
    </visual>
    <collision>
      <origin rpy="0 0 0" xyz="0 0 0.125"/>
      <geometry>
        <cylinder length="0.25" radius="0.01"/>
      </geometry>
    </collision>
    <inertial>
      <origin rpy="0 0 0" xyz="0 0 0.125"/>
      <mass value="1"/>
      <inertia ixx="0.005233333333333333" ixy="0.0" ixz="0.0" iyy="0.005233333333333333" iyz="0.0" izz="0.03125"/>
    </inertial>
  </link>
  <joint name="arm2_joint1" type="revolute">
    <parent link="arm2_base"/>
    <child link="arm2_link1"/>
    <limit effort="30" lower="0" upper="3.141592653589793" velocity="1.0"/>
    <origin rpy="-1.5707963267948966 0 3.141592653589793" xyz=" 0.0       -0.125 0"/>
    <axis xyz="1 0 0"/>
  </joint>
  <joint name="arm2_joint2" type="revolute">
    <parent link="arm2_link1"/>
    <child link="arm2_link2"/>
    <limit effort="30" lower="0" upper="3.141592653589793" velocity="1.0"/>
    <origin rpy="0 0 0" xyz="0 0 0.15"/>
    <axis xyz="1 0 0"/>
  </joint>
  <joint name="arm2_joint3" type="revolute">
    <parent link="arm2_link2"/>
    <child link="arm2_link3"/>
    <limit effort="30" lower="0" upper="3.141592653589793" velocity="1.0"/>
    <origin rpy="0 0 0" xyz="0 0 0.25"/>
    <axis xyz="1 0 0"/>
  </joint>
  <link name="arm3_base"/>
  <link name="arm3_link1">
    <visual>
      <origin rpy="0 0 0" xyz="0 0 0.075"/>
      <geometry>
        <cylinder length="0.15" radius="0.01"/>
      </geometry>
    </visual>
    <collision>
      <origin rpy="0 0 0" xyz="0 0 0.075"/>
      <geometry>
        <cylinder length="0.15" radius="0.01"/>
      </geometry>
    </collision>
    <inertial>
      <origin rpy="0 0 0" xyz="0 0 0.075"/>
      <mass value="1"/>
      <inertia ixx="0.0019" ixy="0.0" ixz="0.0" iyy="0.0019" iyz="0.0" izz="0.01125"/>
    </inertial>
  </link>
  <link name="arm3_link2">
    <visual>
      <origin rpy="0 0 0" xyz="0 0 0.125"/>
      <geometry>
        <cylinder length="0.25" radius="0.01"/>
      </geometry>
    </visual>
    <collision>
      <origin rpy="0 0 0" xyz="0 0 0.125"/>
      <geometry>
        <cylinder length="0.25" radius="0.01"/>
      </geometry>
    </collision>
    <inertial>
      <origin rpy="0 0 0" xyz="0 0 0.125"/>
      <mass value="1"/>
      <inertia ixx="0.005233333333333333" ixy="0.0" ixz="0.0" iyy="0.005233333333333333" iyz="0.0" izz="0.03125"/>
    </inertial>
  </link>
  <link name="arm3_link3">
    <visual>
      <origin rpy="0 0 0" xyz="0 0 0.125"/>
      <geometry>
        <cylinder length="0.25" radius="0.01"/>
      </geometry>
    </visual>
    <collision>
      <origin rpy="0 0 0" xyz="0 0 0.125"/>
      <geometry>
        <cylinder length="0.25" radius="0.01"/>
      </geometry>
    </collision>
    <inertial>
      <origin rpy="0 0 0" xyz="0 0 0.125"/>
      <mass value="1"/>
      <inertia ixx="0.005233333333333333" ixy="0.0" ixz="0.0" iyy="0.005233333333333333" iyz="0.0" izz="0.03125"/>
    </inertial>
  </link>
  <joint name="arm3_joint1" type="revolute">
    <parent link="arm3_base"/>
    <child link="arm3_link1"/>
    <limit effort="30" lower="0" upper="3.141592653589793" velocity="1.0"/>
    <origin rpy="-1.5707963267948966 0 0" xyz=" 0.125 0.125 0"/>
    <axis xyz="1 0 0"/>
  </joint>
  <joint name="arm3_joint2" type="revolute">
    <parent link="arm3_link1"/>
    <child link="arm3_link2"/>
    <limit effort="30" lower="0" upper="3.141592653589793" velocity="1.0"/>
    <origin rpy="0 0 0" xyz="0 0 0.15"/>
    <axis xyz="1 0 0"/>
  </joint>
  <joint name="arm3_joint3" type="revolute">
    <parent link="arm3_link2"/>
    <child link="arm3_link3"/>
    <limit effort="30" lower="0" upper="3.141592653589793" velocity="1.0"/>
    <origin rpy="0 0 0" xyz="0 0 0.25"/>
    <axis xyz="1 0 0"/>
  </joint>
  <!-- Optionally, add a base link or other structure to connect the arms -->
  <link name="world"/>
  <link name="p1"/>
  <link name="p2"/>
  <link name="p3"/>
  <link name="base">
    <visual>
      <geometry>
        <box size="0.25 0.25 0.05"/>
      </geometry>
    </visual>
    <collision>
      <origin rpy="0 0 0" xyz="0 0 0"/>
      <geometry>
        <box size="0.25 0.25 0.05"/>
      </geometry>
    </collision>
    <inertial>
      <origin rpy="0 0 0" xyz="0 0 0"/>
      <mass value="1.0"/>
      <inertia ixx="0.005416666666666667" ixy="0.0" ixz="0.0" iyy="0.005416666666666667" iyz="0.0" izz="0.010416666666666666"/>
    </inertial>
  </link>
  <joint name="x_pos" type="prismatic">
    <parent link="world"/>
    <child link="p1"/>
    <axis xyz="1 0 0"/>
    <limit effort="100" lower="-100" upper="100" velocity="100"/>
  </joint>
  <joint name="y_pos" type="prismatic">
    <parent link="p1"/>
    <child link="p2"/>
    <axis xyz="0 1 0"/>
    <limit effort="100" lower="-100" upper="100" velocity="100"/>
  </joint>
  <joint name="z_pos" type="prismatic">
    <parent link="p2"/>
    <child link="p3"/>
    <axis xyz="0 0 1"/>
    <limit effort="100" lower="-100" upper="100" velocity="100"/>
  </joint>
  <joint name="base_joint" type="continuous">
    <parent link="p3"/>
    <child link="base"/>
    <axis xyz="0 0 1"/>
    <dynamics damping="100.0" friction="0.0"/>
  </joint>
  <joint name="arm1_fix" type="fixed">
    <parent link="base"/>
    <child link="arm1_base"/>
  </joint>
  <joint name="arm2_fix" type="fixed">
    <parent link="base"/>
    <child link="arm2_base"/>
  </joint>
  <joint name="arm3_fix" type="fixed">
    <parent link="base"/>
    <child link="arm3_base"/>
  </joint>
</robot>
